<?xml version="1.0" ?>
<robot name="line" xmlns:xacro="http://www.ros.org/wiki/xacro">

<xacro:include filename="$(find line_description)/urdf/materials.xacro" />
<xacro:include filename="$(find line_description)/urdf/line.trans" />
<xacro:include filename="$(find line_description)/urdf/line.gazebo" />
<link name="base_link">
  <inertial>
    <origin xyz="-0.008355506887426001 2.7103412180322045e-17 -0.0014409659866593677" rpy="0 0 0"/>
    <mass value="0.9878184379632768"/>
    <inertia ixx="0.001127" iyy="0.003679" izz="0.004639" ixy="-0.0" iyz="0.0" ixz="-8.1e-05"/>
  </inertial>
  <visual>
    <origin xyz="0 0 0" rpy="0 0 0"/>
    <geometry>
      <mesh filename="package://line_description/meshes/base_link.stl" scale="0.001 0.001 0.001"/>
    </geometry>
    <material name="silver"/>
  </visual>
  <collision>
    <origin xyz="0 0 0" rpy="0 0 0"/>
    <geometry>
      <mesh filename="package://line_description/meshes/base_link.stl" scale="0.001 0.001 0.001"/>
    </geometry>
  </collision>
</link>

<link name="wheel2_1">
  <inertial>
    <origin xyz="-9.685754837063243e-10 -0.005000000000000011 -2.2351741811588166e-10" rpy="0 0 0"/>
    <mass value="0.34680237652518564"/>
    <inertia ixx="0.000125" iyy="0.000244" izz="0.000125" ixy="0.0" iyz="0.0" ixz="-0.0"/>
  </inertial>
  <visual>
    <origin xyz="0.065 0.055 0.015" rpy="0 0 0"/>
    <geometry>
      <mesh filename="package://line_description/meshes/wheel2_1.stl" scale="0.001 0.001 0.001"/>
    </geometry>
    <material name="silver"/>
  </visual>
  <collision>
    <origin xyz="0.065 0.055 0.015" rpy="0 0 0"/>
    <geometry>
      <mesh filename="package://line_description/meshes/wheel2_1.stl" scale="0.001 0.001 0.001"/>
    </geometry>
  </collision>
</link>

<link name="wheel1_1">
  <inertial>
    <origin xyz="-9.685754837063243e-10 0.005000000000000011 -2.2351741811588166e-10" rpy="0 0 0"/>
    <mass value="0.34680237652518564"/>
    <inertia ixx="0.000125" iyy="0.000244" izz="0.000125" ixy="-0.0" iyz="-0.0" ixz="0.0"/>
  </inertial>
  <visual>
    <origin xyz="0.065 -0.055 0.015" rpy="0 0 0"/>
    <geometry>
      <mesh filename="package://line_description/meshes/wheel1_1.stl" scale="0.001 0.001 0.001"/>
    </geometry>
    <material name="silver"/>
  </visual>
  <collision>
    <origin xyz="0.065 -0.055 0.015" rpy="0 0 0"/>
    <geometry>
      <mesh filename="package://line_description/meshes/wheel1_1.stl" scale="0.001 0.001 0.001"/>
    </geometry>
  </collision>
</link>

<link name="baase2_1">
  <inertial>
    <origin xyz="-0.024999999999999967 0.0 0.0115" rpy="0 0 0"/>
    <mass value="0.50554"/>
    <inertia ixx="0.000229" iyy="9e-05" izz="0.000274" ixy="0.0" iyz="0.0" ixz="0.0"/>
  </inertial>
  <visual>
    <origin xyz="-0.1 -0.0 -0.005" rpy="0 0 0"/>
    <geometry>
      <mesh filename="package://line_description/meshes/baase2_1.stl" scale="0.001 0.001 0.001"/>
    </geometry>
    <material name="silver"/>
  </visual>
  <collision>
    <origin xyz="-0.1 -0.0 -0.005" rpy="0 0 0"/>
    <geometry>
      <mesh filename="package://line_description/meshes/baase2_1.stl" scale="0.001 0.001 0.001"/>
    </geometry>
  </collision>
</link>

<link name="lidar_1">
  <inertial>
    <origin xyz="6.938893903907228e-17 0.0 0.010000000000000012" rpy="0 0 0"/>
    <mass value="0.15105170177541452"/>
    <inertia ixx="1.7e-05" iyy="1.7e-05" izz="2.3e-05" ixy="0.0" iyz="0.0" ixz="0.0"/>
  </inertial>
  <visual>
    <origin xyz="-0.075 -0.0 -0.028" rpy="0 0 0"/>
    <geometry>
      <mesh filename="package://line_description/meshes/lidar_1.stl" scale="0.001 0.001 0.001"/>
    </geometry>
    <material name="silver"/>
  </visual>
  <collision>
    <origin xyz="-0.075 -0.0 -0.028" rpy="0 0 0"/>
    <geometry>
      <mesh filename="package://line_description/meshes/lidar_1.stl" scale="0.001 0.001 0.001"/>
    </geometry>
  </collision>
</link>

<joint name="Rev1" type="continuous">
  <origin xyz="-0.065 -0.055 -0.015" rpy="0 0 0"/>
  <parent link="base_link"/>
  <child link="wheel2_1"/>
  <axis xyz="0.0 -1.0 0.0"/>
</joint>

<joint name="Rev2" type="continuous">
  <origin xyz="-0.065 0.055 -0.015" rpy="0 0 0"/>
  <parent link="base_link"/>
  <child link="wheel1_1"/>
  <axis xyz="0.0 -1.0 0.0"/>
</joint>

<joint name="Rigid3" type="fixed">
  <origin xyz="0.1 0.0 0.005" rpy="0 0 0"/>
  <parent link="base_link"/>
  <child link="baase2_1"/>
</joint>

<joint name="Rev4" type="continuous">
  <origin xyz="-0.025 0.0 0.023" rpy="0 0 0"/>
  <parent link="baase2_1"/>
  <child link="lidar_1"/>
  <axis xyz="0.0 0.0 1.0"/>
</joint>

</robot>
